Workbook

Sheet data
A1: round_number | B1: straights | C1: high_sped_turn | D1: med_speed_turn | E1: low_speed_turn | F1: length_st_m | G1: driver | H1: team | I1: engine_supplier | J1: season_avg_finish_pos | K1: season_avg_quali_pos | L1: last3_avg_finish | M1: last3_avg_quali | N1: season_points | O1: championship_position | P1: team_championship_position | Q1: team_points | R1: team_avg_finish_pos | S1: team_avg_quali_pos | T1: track_avg_finish_pos | U1: track_avg_quali_pos | V1: track_wins | W1: track_podiums | X1: driver_mechanical_dnf_rate | Y1: team_mechanical_dnfs_this_season | Z1: engine_manufacturer_mechanical_dnfs_this_season | AA1: fp1_gap_to_fastest | AB1: fp2_gap_to_fastest | AC1: fp3_gap_to_fastest | AD1: race_or_sprint | AE1: sprint_quali_gap | AF1: sprint_finish_pos | AG1: quali_gap_to_pole | AH1: race_winner
A2: 1 | B2: 5 | C2: 4 | D2: 6 | E2: 4 | F2: 2100 | G2: 63 | H2: 1 | I2: 1 | J2: 10 | K2: 10 | L2: 10 | M2: 10 | N2: 0 | O2: 1 | P2: 1 | Q2: 0 | R2: 22 | S2: 22 | T2: 8 | U2: 6.5 | V2: 1 | W2: 3 | X2: 0 | Y2: 0 | Z2: 0 | AA2: 1.104 | AB2: ='Round Data'!E3 -> 0.32 | AC2: ='Round Data'!E29 -> 0 | AD2: 0 | AE2: 0 | AF2: 0 | AG2: ='Round Data'!O3 -> 0 | AH2: 1
A3: 1 | B3: 5 | C3: 4 | D3: 6 | E3: 4 | F3: 2100 | G3: 12 | H3: 1 | I3: 1 | J3: 10 | K3: 10 | L3: 10 | M3: 10 | N3: 0 | O3: 1 | P3: 1 | Q3: 0 | R3: 22 | S3: 22 | T3: 3 | U3: 9 | V3: 0 | W3: 1 | X3: 0 | Y3: 0 | Z3: 0 | AA3: 1.109 | AB3: ='Round Data'!E4 -> 0.214 | AC3: ='Round Data'!E30 -> 1.271 | AD3: 0 | AE3: 0 | AF3: 0 | AG3: ='Round Data'!O4 -> 0.293 | AH3: 0
A4: 1 | B4: 5 | C4: 4 | D4: 6 | E4: 4 | F4: 2100 | G4: 16 | H4: 2 | I4: 2 | J4: 10 | K4: 10 | L4: 10 | M4: 10 | N4: 0 | O4: 1 | P4: 1 | Q4: 0 | R4: 22 | S4: 22 | T4: 5.33 | U4: 6.57 | V4: 1 | W4: 3 | X4: 0 | Y4: 0 | Z4: 0 | AA4: 0 | AB4: ='Round Data'!E5 -> 0.562 | AC4: ='Round Data'!E31 -> 0.774 | AD4: 0 | AE4: 0 | AF4: 0 | AG4: ='Round Data'!O5 -> 0.809 | AH4: 0
A5: 1 | B5: 5 | C5: 4 | D5: 6 | E5: 4 | F5: 2100 | G5: 44 | H5: 2 | I5: 2 | J5: 10 | K5: 10 | L5: 10 | M5: 10 | N5: 0 | O5: 1 | P5: 1 | Q5: 0 | R5: 22 | S5: 22 | T5: 3.27 | U5: 4.44 | V5: 2 | W5: 10 | X5: 0 | Y5: 0 | Z5: 0 | AA5: 0.469 | AB5: ='Round Data'!E6 -> 0.321 | AC5: ='Round Data'!E32 -> 0.616 | AD5: 0 | AE5: 0 | AF5: 0 | AG5: ='Round Data'!O6 -> 0.96 | AH5: 0
A6: 1 | B6: 5 | C6: 4 | D6: 6 | E6: 4 | F6: 2100 | G6: 1 | H6: 3 | I6: 1 | J6: 10 | K6: 10 | L6: 10 | M6: 10 | N6: 0 | O6: 1 | P6: 1 | Q6: 0 | R6: 22 | S6: 22 | T6: 5.33 | U6: 5.83 | V6: 1 | W6: 2 | X6: 0 | Y6: 0 | Z6: 0 | AA6: 4.124 | AB6: ='Round Data'!E7 -> 1.065 | AC6: ='Round Data'!E33 -> 1.39 | AD6: 0 | AE6: 0 | AF6: 0 | AG6: ='Round Data'!O7 -> 0.957 | AH6: 0
A7: 1 | B7: 5 | C7: 4 | D7: 6 | E7: 4 | F7: 2100 | G7: 81 | H7: 3 | I7: 1 | J7: 10 | K7: 10 | L7: 10 | M7: 10 | N7: 0 | O7: 1 | P7: 1 | Q7: 0 | R7: 22 | S7: 22 | T7: 7 | U7: 7 | V7: 0 | W7: 0 | X7: 0 | Y7: 0 | Z7: 0 | AA7: 1.046 | AB7: ='Round Data'!E8 -> 0 | AC7: ='Round Data'!E34 -> 1.034 | AD7: 0 | AE7: 0 | AF7: 0 | AG7: ='Round Data'!O8 -> 0.862 | AH7: 0
A8: 1 | B8: 5 | C8: 4 | D8: 6 | E8: 4 | F8: 2100 | G8: 3 | H8: 4 | I8: 3 | J8: 10 | K8: 10 | L8: 10 | M8: 10 | N8: 0 | O8: 1 | P8: 1 | Q8: 0 | R8: 22 | S8: 22 | T8: 4.71 | U8: 5.6 | V8: 1 | W8: 3 | X8: 0 | Y8: 0 | Z8: 0 | AA8: 0.522 | AB8: ='Round Data'!E9 -> 0.637 | AC8: ='Round Data'!E35 -> 1.144 | AD8: 0 | AE8: 0 | AF8: 0 | AG8: ='Round Data'!O9 -> 41.481 | AH8: 0
A9: 1 | B9: 5 | C9: 4 | D9: 6 | E9: 4 | F9: 2100 | G9: 6 | H9: 4 | I9: 3 | J9: 10 | K9: 10 | L9: 10 | M9: 10 | N9: 0 | O9: 1 | P9: 1 | Q9: 0 | R9: 22 | S9: 22 | T9: 7 | U9: 20 | V9: 0 | W9: 0 | X9: 0 | Y9: 0 | Z9: 0 | AA9: 0.82 | AB9: ='Round Data'!E10 -> 1.212 | AC9: ='Round Data'!E36 -> 1.084 | AD9: 0 | AE9: 0 | AF9: 0 | AG9: ='Round Data'!O10 -> 0.785 | AH9: 0
A10: 2 | B10: 4 | C10: 4 | D10: 6 | E10: 6 | F10: 1935 | G10: 63 | H10: 1 | I10: 1 | J10: 1 | K10: 1 | L10: 1 | M10: 1 | N10: 25 | O10: 1 | P10: 1 | Q10: =SUM(N10:N11) -> 43 | R10: =SUM(J10:J11)/2 -> 1.5 | S10: =SUM(K10:K11)/2 -> 1.5 | T10: 6.75 | U10: 7.25 | V10: 0 | W10: 1 | X10: 0 | Y10: 0 | Z10: 2 | AA10: 0 | AB10: 0 | AC10: 0 | AD10: 1 | AE10: 0 | AF10: 1 | AG10: 0.222 | AH10: 0
A11: 2 | B11: 4 | C11: 4 | D11: 6 | E11: 6 | F11: 1935 | G11: 12 | H11: 1 | I11: 1 | J11: 2 | K11: 2 | L11: 2 | M11: 2 | N11: 18 | O11: 2 | P11: 1 | Q11: =Q10 -> 43 | R11: =R10 -> 1.5 | S11: =S10 -> 1.5 | T11: 3.5 | U11: 4.5 | V11: 0 | W11: 0 | X11: 0 | Y11: 0 | Z11: 2 | AA11: 0.12 | AB11: 0 | AC11: 0 | AD11: 1 | AE11: 0.289 | AF11: 5 | AG11: 0 | AH11: 1
A12: 2 | B12: 4 | C12: 4 | D12: 6 | E12: 6 | F12: 1935 | G12: 16 | H12: 2 | I12: 2 | J12: 3 | K12: 4 | L12: 3 | M12: 4 | N12: 15 | O12: 3 | P12: 2 | Q12: =N12+N13 -> 27 | R12: =(J12+J13)/2 -> 3.5 | S12: =(K12+K13)/2 -> 5.5 | T12: 8 | U12: 7.8 | V12: 0 | W12: 0 | X12: 0 | Y12: 0 | Z12: 1 | AA12: 0.858 | AB12: 0 | AC12: 0 | AD12: 1 | AE12: 1.008 | AF12: 2 | AG12: 0.364 | AH12: 0
A13: 2 | B13: 4 | C13: 4 | D13: 6 | E13: 6 | F13: 1935 | G13: 44 | H13: 2 | I13: 2 | J13: 4 | K13: 7 | L13: 4 | M13: 7 | N13: 12 | O13: 4 | P13: 2 | Q13: =Q12 -> 27 | R13: =R12 -> 3.5 | S13: =S12 -> 5.5 | T13: 3.07 | U13: 5.31 | V13: 6 | W13: 10 | X13: 0 | Y13: 0 | Z13: 1 | AA13: 1.388 | AB13: 0 | AC13: 0 | AD13: 1 | AE13: 0.641 | AF13: 3 | AG13: 0.315 | AH13: 0
A14: 2 | B14: 4 | C14: 4 | D14: 6 | E14: 6 | F14: 1935 | G14: 1 | H14: 3 | I14: 1 | J14: 5 | K14: 6 | L14: 5 | M14: 6 | N14: 10 | O14: 5 | P14: 3 | Q14: =N14+N15 -> 10 | R14: =(J14+J15)/2 -> 13 | S14: =(K14+K15)/2 -> 5.5 | T14: 7.33 | U14: 7 | V14: 0 | W14: 2 | X14: 0 | Y14: 1 | Z14: 2 | AA14: 0.555 | AB14: 0 | AC14: 0 | AD14: 1 | AE14: 0.621 | AF14: 4 | AG14: 0.544 | AH14: 0
A15: 2 | B15: 4 | C15: 4 | D15: 6 | E15: 6 | F15: 1935 | G15: 81 | H15: 3 | I15: 1 | J15: 21 | K15: 5 | L15: 21 | M15: 5 | N15: 0 | O15: 21 | P15: 3 | Q15: =Q14 -> 10 | R15: =R14 -> 13 | S15: =S14 -> 5.5 | T15: 4.5 | U15: 3.67 | V15: 1 | W15: 1 | X15: 1 | Y15: 1 | Z15: 2 | AA15: 0.731 | AB15: 0 | AC15: 0 | AD15: 1 | AE15: 0.704 | AF15: 6 | AG15: 0.486 | AH15: 0
A16: 2 | B16: 4 | C16: 4 | D16: 6 | E16: 6 | F16: 1935 | G16: 3 | H16: 4 | I16: 3 | J16: 6 | K16: 20 | L16: 6 | M16: 20 | N16: 8 | O16: 6 | P16: 4 | Q16: =SUM(N16:N17) -> 8 | R16: =SUM(J16:J17)/2 -> 13 | S16: =SUM(K16:K17)/2 -> 11.5 | T16: 6 | U16: 7.63 | V16: 1 | W16: 2 | X16: 0 | Y16: 0 | Z16: 1 | AA16: 1.8 | AB16: 0 | AC16: 0 | AD16: 1 | AE16: 1.734 | AF16: 9 | AG16: 0.938 | AH16: 0
A17: 2 | B17: 4 | C17: 4 | D17: 6 | E17: 6 | F17: 1935 | G17: 6 | H17: 4 | I17: 3 | J17: 20 | K17: 3 | L17: 20 | M17: 3 | N17: 0 | O17: 14 | P17: 4 | Q17: =Q16 -> 8 | R17: =R16 -> 13 | S17: =S16 -> 11.5 | T17: 9.5 | U17: 8 | V17: 0 | W17: 0 | X17: 1 | Y17: 1 | Z17: 1 | AA17: 2.115 | AB17: 0 | AC17: 0 | AD17: 1 | AE17: 2.203 | AF17: 15 | AG17: 1.288 | AH17: 0
A18: 3 | B18: 2 | C18: 6 | D18: 8 | E18: 4 | F18: 1800 | G18: 63 | H18: 1 | I18: 1 | J18: 1.5 | K18: 1.5 | L18: 1.5 | M18: 1.5 | N18: 43 | O18: 1 | P18: 1 | Q18: =SUM(N18:N19) -> 86 | R18: =SUM(J18:J19)/2 -> 1.5 | S18: =SUM(K18:K19)/2 -> 1.5 | T18: 7.83 | U18: 8.33 | V18: 0 | W18: 0 | X18: 0 | Y18: 0 | Z18: 5 | AA18: ='Round Data'!E56 -> 0 | AB18: ='Round Data'!L56 -> 0.205 | AC18: ='Round Data'!T56 -> 0.254 | AD18: 0 | AE18: 0 | AF18: 0 | AG18: ='Round Data'!H81 -> 0.298 | AH18: 0
A19: 3 | B19: 2 | C19: 6 | D19: 8 | E19: 4 | F19: 1800 | G19: 12 | H19: 1 | I19: 1 | J19: 1.5 | K19: 1.5 | L19: 1.5 | M19: 1.5 | N19: 43 | O19: 2 | P19: 1 | Q19: =Q18 -> 86 | R19: =R18 -> 1.5 | S19: =S18 -> 1.5 | T19: 3.5 | U19: 3.5 | V19: 0 | W19: 0 | X19: 0 | Y19: 0 | Z19: =Z11+3 -> 5 | AA19: ='Round Data'!E57 -> 0.026 | AB19: ='Round Data'!L57 -> 0.092 | AC19: ='Round Data'!T57 -> 0 | AD19: 0 | AE19: 0 | AF19: 0 | AG19: ='Round Data'!H82 -> 0 | AH19: 1
A20: 3 | B20: 2 | C20: 6 | D20: 8 | E20: 4 | F20: 1800 | G20: 16 | H20: 2 | I20: 2 | J20: 3.5 | K20: 4 | L20: 3.5 | M20: 4 | N20: =N12+19 -> 34 | O20: 3 | P20: 2 | Q20: =N20+N21 -> 61 | R20: =(J20+J21)/2 -> 3.5 | S20: =(K20+K21)/2 -> 4.5 | T20: 4 | U20: 4.86 | V20: 0 | W20: 2 | X20: 0 | Y20: 0 | Z20: 1 | AA20: ='Round Data'!E58 -> 0.289 | AB20: ='Round Data'!L58 -> 0.713 | AC20: ='Round Data'!T58 -> 0.867 | AD20: 0 | AE20: 0 | AF20: 0 | AG20: ='Round Data'!H83 -> 0.627 | AH20: 0
A21: 3 | B21: 2 | C21: 6 | D21: 8 | E21: 4 | F21: 1800 | G21: 44 | H21: 2 | I21: 2 | J21: 3.5 | K21: 5 | L21: 3.5 | M21: 5 | N21: 27 | O21: 4 | P21: 2 | Q21: =Q20 -> 61 | R21: =R20 -> 3.5 | S21: =S20 -> 4.5 | T21: 4 | U21: 4.5 | V21: 5 | W21: 7 | X21: 0 | Y21: 0 | Z21: 1 | AA21: ='Round Data'!E59 -> 0.374 | AB21: ='Round Data'!L59 -> 0.847 | AC21: ='Round Data'!T59 -> 1.021 | AD21: 0 | AE21: 0 | AF21: 0 | AG21: ='Round Data'!H84 -> 0.789 | AH21: 0
A22: 3 | B22: 2 | C22: 6 | D22: 8 | E22: 4 | F22: 1800 | G22: 1 | H22: 3 | I22: 1 | J22: 12.5 | K22: 6 | L22: 12.5 | M22: 6 | N22: 15 | O22: 5 | P22: 3 | Q22: =N22+N23 -> 18 | R22: =(J22+J23)/2 -> 16.25 | S22: =(K22+K23)/2 -> 5.5 | T22: 5.83 | U22: 5.17 | V22: 0 | W22: 2 | X22: 1 | Y22: 3 | Z22: =Z14+3 -> 5 | AA22: ='Round Data'!E60 -> 0.132 | AB22: ='Round Data'!L60 -> 0.516 | AC22: ='Round Data'!T60 -> 1.238 | AD22: 0 | AE22: 0 | AF22: 0 | AG22: ='Round Data'!H85 -> 0.631 | AH22: 0
A23: 3 | B23: 2 | C23: 6 | D23: 8 | E23: 4 | F23: 1800 | G23: 81 | H23: 3 | I23: 1 | J23: 20 | K23: 5 | L23: 20 | M23: 5 | N23: 3 | O23: 20 | P23: 3 | Q23: =Q22 -> 18 | R23: =R22 -> 16.25 | S23: =S22 -> 5.5 | T23: 4 | U23: 3.5 | V23: 0 | W23: 3 | X23: 2 | Y23: 3 | Z23: =Z15+3 -> 5 | AA23: ='Round Data'!E61 -> 0.199 | AB23: ='Round Data'!L61 -> 0 | AC23: ='Round Data'!T61 -> 1.002 | AD23: 0 | AE23: 0 | AF23: 0 | AG23: ='Round Data'!H86 -> 0.354 | AH23: 0
A24: 3 | B24: 2 | C24: 6 | D24: 8 | E24: 4 | F24: 1800 | G24: 3 | H24: 4 | I24: 3 | J24: 11 | K24: 14 | L24: 11 | M24: 14 | N24: 8 | O24: 10 | P24: 4 | Q24: =SUM(N24:N25) -> 12 | R24: =SUM(J24:J25)/2 -> 12.5 | S24: =SUM(K24:K25)/2 -> 10 | T24: 3.11 | U24: 4.7 | V24: 4 | W24: 7 | X24: 1 | Y24: 2 | Z24: 2 | AA24: ='Round Data'!E62 -> 0.791 | AB24: ='Round Data'!L62 -> 1.376 | AC24: ='Round Data'!T62 -> 1.548 | AD24: 0 | AE24: 0 | AF24: 0 | AG24: ='Round Data'!H87 -> 1.484 | AH24: 0
A25: 3 | B25: 2 | C25: 6 | D25: 8 | E25: 4 | F25: 1800 | G25: 6 | H25: 4 | I25: 3 | J25: 14 | K25: 6 | L25: 14 | M25: 6 | N25: 4 | O25: 12 | P25: 4 | Q25: =Q24 -> 12 | R25: =R24 -> 12.5 | S25: =S24 -> 10 | T25: 10 | U25: 7.5 | V25: 0 | W25: 0 | X25: 1 | Y25: 2 | Z25: 2 | AA25: ='Round Data'!E63 -> 1.137 | AB25: ='Round Data'!L63 -> 1.626 | AC25: ='Round Data'!T63 -> 1.732 | AD25: 0 | AE25: 0 | AF25: 0 | AG25: ='Round Data'!H88 -> 1.2 | AH25: 0
A26: 4 | B26: 3 | C26: 6 | D26: 7 | E26: 6 | F26: 3100 | G26: 63 | H26: 1 | I26: 1 | J26: 2.3333333 | K26: 1.6666667 | L26: 2.3333333 | M26: 1.6666667 | N26: 55 | O26: 2 | P26: 1 | Q26: =SUM(N26:N27) -> 123 | R26: =SUM(J26:J27)/2 -> 1.8333333 | S26: =SUM(K26:K27)/2 -> 1.5 | T26: 4.8 | U26: 7 | V26: 0 | W26: 1 | X26: 0 | Y26: 0 | Z26: 5 | AA26: ='Round Data'!E107 -> 0.79 | AB26: 0 | AC26: 0 | AD26: 1 | AE26: ='Round Data'!P107 -> 0.624 | AF26: 4 | AG26: ='Round Data'!Y107 -> 0.399 | AH26: 0
A27: 4 | B27: 3 | C27: 6 | D27: 7 | E27: 6 | F27: 3100 | G27: 12 | H27: 1 | I27: 1 | J27: 1.3333333 | K27: 1.3333333 | L27: 1.3333333 | M27: 1.3333333 | N27: 68 | O27: 1 | P27: 1 | Q27: =Q26 -> 123 | R27: =R26 -> 1.8333333 | S27: =S26 -> 1.5 | T27: 3.5 | U27: 1.5 | V27: 0 | W27: 0 | X27: 0 | Y27: 0 | Z27: =Z19+0 -> 5 | AA27: ='Round Data'!E108 -> 0.769 | AB27: 0 | AC27: 0 | AD27: 1 | AE27: ='Round Data'!P108 -> 0.222 | AF27: 6 | AG27: ='Round Data'!Y108 -> 0 | AH27: 1
A28: 4 | B28: 3 | C28: 6 | D28: 7 | E28: 6 | F28: 3100 | G28: 16 | H28: 2 | I28: 2 | J28: 3.3333333 | K28: 4 | L28: 3.3333333 | M28: 4 | N28: =N20+15 -> 49 | O28: 3 | P28: 2 | Q28: =N28+N29 -> 84 | R28: =(J28+J29)/2 -> 3.8333333 | S28: =(K28+K29)/2 -> 4.6666667 | T28: 5.4 | U28: 4.2 | V28: 0 | W28: 2 | X28: 0 | Y28: 0 | Z28: 1 | AA28: ='Round Data'!E109 -> 0 | AB28: 0 | AC28: 0 | AD28: 1 | AE28: ='Round Data'!P109 -> 0.37 | AF28: 3 | AG28: ='Round Data'!Y109 -> 0.345 | AH28: 0
A29: 4 | B29: 3 | C29: 6 | D29: 7 | E29: 6 | F29: 3100 | G29: 44 | H29: 2 | I29: 2 | J29: 4.3333333 | K29: 5.3333333 | L29: 4.3333333 | M29: 5.3333333 | N29: 35 | O29: 4 | P29: 2 | Q29: =Q28 -> 84 | R29: =R28 -> 3.8333333 | S29: =S28 -> 4.6666667 | T29: 6.4 | U29: 9 | V29: 0 | W29: 0 | X29: 0 | Y29: 0 | Z29: 1 | AA29: ='Round Data'!E110 -> 0.467 | AB29: 0 | AC29: 0 | AD29: 1 | AE29: ='Round Data'!P110 -> 0.749 | AF29: 7 | AG29: ='Round Data'!Y110 -> 0.521 | AH29: 0
A30: 4 | B30: 3 | C30: 6 | D30: 7 | E30: 6 | F30: 3100 | G30: 1 | H30: 3 | I30: 1 | J30: 10 | K30: 5.6666667 | L30: 10 | M30: 5.6666667 | N30: 25 | O30: 5 | P30: 3 | Q30: =N30+N31 -> 46 | R30: =(J30+J31)/2 -> 12 | S30: =(K30+K31)/2 -> 5 | T30: 5.5 | U30: 7 | V30: 1 | W30: 3 | X30: 1 | Y30: 3 | Z30: =Z22+0 -> 5 | AA30: ='Round Data'!E111 -> 0.898 | AB30: 0 | AC30: 0 | AD30: 1 | AE30: ='Round Data'!P111 -> 0 | AF30: 1 | AG30: ='Round Data'!Y111 -> 0.385 | AH30: 0
A31: 4 | B31: 3 | C31: 6 | D31: 7 | E31: 6 | F31: 3100 | G31: 81 | H31: 3 | I31: 1 | J31: 14 | K31: 4.3333333 | L31: 14 | M31: 4.3333333 | N31: 21 | O31: 20 | P31: 3 | Q31: =Q30 -> 46 | R31: =R30 -> 12 | S31: =S30 -> 5 | T31: 9 | U31: 9 | V31: 1 | W31: 2 | X31: 2 | Y31: 3 | Z31: =Z23+0 -> 5 | AA31: ='Round Data'!E112 -> 0.448 | AB31: 0 | AC31: 0 | AD31: 1 | AE31: ='Round Data'!P112 -> 0.239 | AF31: 2 | AG31: ='Round Data'!Y112 -> 0.702 | AH31: 0
A32: 4 | B32: 3 | C32: 6 | D32: 7 | E32: 6 | F32: 3100 | G32: 3 | H32: 4 | I32: 3 | J32: 10 | K32: 13 | L32: 10 | M32: 13 | N32: 12 | O32: 9 | P32: 4 | Q32: =SUM(N32:N33) -> 16 | R32: =SUM(J32:J33)/2 -> 11.666667 | S32: =SUM(K32:K33)/2 -> 9.8333333 | T32: 2.6 | U32: 3.2 | V32: 2 | W32: 3 | X32: 1 | Y32: 2 | Z32: 2 | AA32: ='Round Data'!E113 -> 0.297 | AB32: 0 | AC32: 0 | AD32: 1 | AE32: ='Round Data'!P113 -> 0.592 | AF32: 5 | AG32: ='Round Data'!Y113 -> 0.166 | AH32: 0
A33: 4 | B33: 3 | C33: 6 | D33: 7 | E33: 6 | F33: 3100 | G33: 6 | H33: 4 | I33: 3 | J33: 13.333333 | K33: 6.6666667 | L33: 13.333333 | M33: 6.6666667 | N33: 4 | O33: 14 | P33: 4 | Q33: =Q32 -> 16 | R33: =R32 -> 11.666667 | S33: =S32 -> 9.8333333 | T33: 11 | U33: 16.5 | V33: 0 | W33: 0 | X33: 1 | Y33: 2 | Z33: 2 | AA33: ='Round Data'!E114 -> 1.563 | AB33: 0 | AC33: 0 | AD33: 1 | AE33: ='Round Data'!P114 -> 1.553 | AF33: 9 | AG33: ='Round Data'!Y114 -> 59.99 | AH33: 0
A34: 5 | B34: 4 | C34: 3 | D34: 7 | E34: 4 | F34: 1950 | G34: 63 | H34: 1 | I34: 1 | J34: 2.75 | K34: 2.5 | L34: 3.3333333 | M34: 3 | N34: 67 | O34: 2 | P34: 1 | Q34: =SUM(N34:N35) -> 167 | R34: =SUM(J34:J35)/2 -> 2 | S34: =SUM(K34:K35)/2 -> 1.875 | T34: 6 | U34: 5.5 | V34: 1 | W34: 2 | X34: 0 | Y34: 0 | Z34: 6 | AA34: ='Round Data'!E133 -> 0.142 | AB34: 0 | AC34: 0 | AD34: 1 | AE34: ='Round Data'!P133 -> 0 | AF34: 1 | AG34: ='Round Data'!Y133 -> 0 | AH34: 0
A35: 5 | B35: 4 | C35: 3 | D35: 7 | E35: 4 | F35: 1950 | G35: 12 | H35: 1 | I35: 1 | J35: 1.25 | K35: 1.25 | L35: 1 | M35: 1 | N35: 100 | O35: 1 | P35: 1 | Q35: =Q34 -> 167 | R35: =R34 -> 2 | S35: =S34 -> 1.875 | T35: 2 | U35: 3 | V35: 0 | W35: 1 | X35: 0 | Y35: 0 | Z35: =Z27+1 -> 6 | AA35: ='Round Data'!E134 -> 0 | AB35: 0 | AC35: 0 | AD35: 1 | AE35: ='Round Data'!P134 -> 0.068 | AF35: 3 | AG35: ='Round Data'!Y134 -> 0.068 | AH35: 1
A36: 5 | B36: 4 | C36: 3 | D36: 7 | E36: 4 | F36: 1950 | G36: 16 | H36: 2 | I36: 2 | J36: 4.5 | K36: 3.75 | L36: 5 | M36: 3.6666667 | N36: =N28+4+6 -> 59 | O36: 3 | P36: 2 | Q36: =N36+N37 -> 110 | R36: =(J36+J37)/2 -> 4.625 | S36: =(K36+K37)/2 -> 4.625 | T36: 5.17 | U36: 10.29 | V36: 0 | W36: 1 | X36: 0 | Y36: 0 | Z36: 1 | AA36: ='Round Data'!E135 -> 0.953 | AB36: 0 | AC36: 0 | AD36: 1 | AE36: ='Round Data'!P135 -> 0.445 | AF36: 5 | AG36: ='Round Data'!Y135 -> 0.398 | AH36: 0
A37: 5 | B37: 4 | C37: 3 | D37: 7 | E37: 4 | F37: 1950 | G37: 44 | H37: 2 | I37: 2 | J37: 4.75 | K37: 5.5 | L37: 5 | M37: 5 | N37: 51 | O37: 4 | P37: 2 | Q37: =Q36 -> 110 | R37: =R36 -> 4.625 | S37: =S36 -> 4.625 | T37: 2.36 | U37: 2.76 | V37: 7 | W37: 9 | X37: 0 | Y37: 0 | Z37: 1 | AA37: ='Round Data'!E136 -> 0.774 | AB37: 0 | AC37: 0 | AD37: 1 | AE37: ='Round Data'!P136 -> 0.361 | AF37: 6 | AG37: ='Round Data'!Y136 -> 0.29 | AH37: 0
A38: 5 | B38: 4 | C38: 3 | D38: 7 | E38: 4 | F38: 1950 | G38: 1 | H38: 3 | I38: 1 | J38: 8 | K38: 5.25 | L38: 9 | M38: 5 | N38: 51 | O38: 5 | P38: 3 | Q38: =N38+N39 -> 94 | R38: =(J38+J39)/2 -> 9.625 | S38: =(K38+K39)/2 -> 5.125 | T38: 12 | U38: 7 | V38: 0 | W38: 1 | X38: 1 | Y38: 3 | Z38: =Z30+1 -> 6 | AA38: ='Round Data'!E137 -> 1.397 | AB38: 0 | AC38: 0 | AD38: 1 | AE38: ='Round Data'!P137 -> 0.315 | AF38: 2 | AG38: ='Round Data'!Y137 -> 0.151 | AH38: 0
A39: 5 | B39: 4 | C39: 3 | D39: 7 | E39: 4 | F39: 1950 | G39: 81 | H39: 3 | I39: 1 | J39: 11.25 | K39: 5 | L39: 8 | M39: 5 | N39: 43 | O39: 6 | P39: 3 | Q39: =Q38 -> 94 | R39: =R38 -> 9.625 | S39: =S38 -> 5.125 | T39: 7.75 | U39: 4.75 | V39: 0 | W39: 0 | X39: 2 | Y39: 3 | Z39: =Z31+1 -> 6 | AA39: ='Round Data'!E138 -> 1.561 | AB39: 0 | AC39: 0 | AD39: 1 | AE39: ='Round Data'!P138 -> 0.334 | AF39: 4 | AG39: ='Round Data'!Y138 -> 0.203 | AH39: 0
A40: 5 | B40: 4 | C40: 3 | D40: 7 | E40: 4 | F40: 1950 | G40: 3 | H40: 4 | I40: 3 | J40: 8.75 | K40: 10.25 | L40: 9.6666667 | M40: 7 | N40: 22 | O40: 7 | P40: 4 | Q40: =SUM(N40:N41) -> 26 | R40: =SUM(J40:J41)/2 -> 12.125 | S40: =SUM(K40:K41)/2 -> 10.375 | T40: 3.89 | U40: 5.3 | V40: 3 | W40: 6 | X40: 1 | Y40: 3 | Z40: 3 | AA40: ='Round Data'!E139 -> 0.964 | AB40: 0 | AC40: 0 | AD40: 1 | AE40: ='Round Data'!P139 -> 0.539 | AF40: 7 | AG40: ='Round Data'!Y139 -> 0.329 | AH40: 0
...

Sheet Round Data
A1: FP2 | H1: Quali | R1: Sgrid
A2: Pos. | B2: No. | C2: Driver | D2: Team | E2: Time / Gap | F2: Laps | H2: Pos. | I2: No. | J2: Driver | K2: Team | L2: Q1 | M2: Q2 | N2: Q3 | O2: Gap | P2: Laps | R2: Pos. | S2: No. | T2: Driver | U2: Team | V2: Time
A3: 3 | B3: 63 | C3: George RussellRUS | D3: Mercedes | E3: 0.32 | F3: 28 | H3: 1 | I3: 63 | J3: George RussellRUS | K3: Mercedes | L3: 19.507 | M3: 18.934 | N3: 18.518 | O3: 0 | P3: 22 | R3: 1 | S3: 63 | T3: George RussellRUS | U3: Mercedes | V3: 1:18.518
A4: 2 | B4: 12 | C4: Kimi AntonelliANT | D4: Mercedes | E4: 0.214 | F4: 31 | H4: 2 | I4: 12 | J4: Kimi AntonelliANT | K4: Mercedes | L4: 20.12 | M4: 19.435 | N4: 18.811 | O4: =Table_1__3[[#This Row],[Q3]]-N3 -> 0.293 | P4: 18 | R4: 2 | S4: 12 | T4: Kimi AntonelliANT | U4: Mercedes | V4: 1:18.811
A5: 5 | B5: 16 | C5: Charles LeclercLEC | D5: Ferrari | E5: 0.562 | F5: 30 | H5: 4 | I5: 16 | J5: Charles LeclercLEC | K5: Ferrari | L5: 20.226 | M5: 19.357 | N5: 19.327 | O5: =Table_1__3[[#This Row],[Q3]]-$N$3 -> 0.809 | P5: 24 | R5: 4 | S5: 16 | T5: Charles LeclercLEC | U5: Ferrari | V5: 1:19.327
A6: 4 | B6: 44 | C6: Lewis HamiltonHAM | D6: Ferrari | E6: 0.321 | F6: 32 | H6: 7 | I6: 44 | J6: Lewis HamiltonHAM | K6: Ferrari | L6: 19.811 | M6: 19.921 | N6: 19.478 | O6: =Table_1__3[[#This Row],[Q3]]-$N$3 -> 0.96 | P6: 25 | R6: 7 | S6: 44 | T6: Lewis HamiltonHAM | U6: Ferrari | V6: 1:19.478
A7: 7 | B7: 1 | C7: Lando NorrisNOR | D7: McLaren | E7: 1.065 | F7: 29 | H7: 6 | I7: 1 | J7: Lando NorrisNOR | K7: McLaren | L7: 20.01 | M7: 19.882 | N7: 19.475 | O7: =Table_1__3[[#This Row],[Q3]]-$N$3 -> 0.957 | P7: 26 | R7: 6 | S7: 1 | T7: Lando NorrisNOR | U7: McLaren | V7: 1:19.475
A8: 1 | B8: 81 | C8: Oscar PiastriPIA | D8: McLaren | E8: 0 | F8: 26 | H8: 5 | I8: 81 | J8: Oscar PiastriPIA | K8: McLaren | L8: 19.664 | M8: 19.525 | N8: 19.38 | O8: =Table_1__3[[#This Row],[Q3]]-$N$3 -> 0.862 | P8: 26 | R8: 5 | S8: 81 | T8: Oscar PiastriPIA | U8: McLaren | V8: 1:19.380
A9: 6 | B9: 3 | C9: Max VerstappenVER | D9: Red Bull Racing | E9: 0.637 | F9: 13 | I9: 3 | J9: Max VerstappenVER | K9: Red Bull Racing | L9: 59.999 | O9: =Table_1__3[[#This Row],[Q1]]-N3 -> 41.481 | R9: 20 | S9: 3 | T9: Max VerstappenVER | U9: Red Bull Racing
A10: 9 | B10: 6 | C10: Isack HadjarHAD | D10: Red Bull Racing | E10: 1.212 | F10: 28 | H10: 3 | I10: 6 | J10: Isack HadjarHAD | K10: Red Bull Racing | L10: 20.023 | M10: 19.653 | N10: 19.303 | O10: =Table_1__3[[#This Row],[Q3]]-$N$3 -> 0.785 | P10: 19 | R10: 3 | S10: 6 | T10: Isack HadjarHAD | U10: Red Bull Racing | V10: 1:19.303
A11: 16 | B11: 10 | C11: Pierre GaslyGAS | D11: Alpine | E11: 2.438 | F11: 16 | H11: 14 | I11: 10 | J11: Pierre GaslyGAS | K11: Alpine | L11: 21.138 | M11: 20.501 | O11: =Table_1__3[[#This Row],[Q2]]-$N$3 -> 1.983 | P11: 18 | R11: 14 | S11: 10 | T11: Pierre GaslyGAS | U11: Alpine | V11: 1:20.501
A12: 18 | B12: 43 | C12: Franco ColapintoCOL | D12: Alpine | E12: 2.89 | F12: 27 | H12: 16 | I12: 43 | J12: Franco ColapintoCOL | K12: Alpine | L12: 21.2 | M12: 21.27 | O12: =Table_1__3[[#This Row],[Q2]]-$N$3 -> 2.752 | P12: 18 | R12: 16 | S12: 43 | T12: Franco ColapintoCOL | U12: Alpine | V12: 1:21.270
A13: 13 | B13: 30 | C13: Liam LawsonLAW | D13: Racing Bulls | E13: 1.629 | F13: 29 | H13: 8 | I13: 30 | J13: Liam LawsonLAW | K13: Racing Bulls | L13: 20.491 | M13: 20.144 | N13: 19.994 | O13: =Table_1__3[[#This Row],[Q3]]-$N$3 -> 1.476 | P13: 24 | R13: 8 | S13: 30 | T13: Liam LawsonLAW | U13: Racing Bulls | V13: 1:19.994
A14: 8 | B14: 41 | C14: Arvid LindbladLIN | D14: Racing Bulls | E14: 1.193 | F14: 30 | H14: 9 | I14: 41 | J14: Arvid LindbladLIN | K14: Racing Bulls | L14: 20.409 | M14: 19.971 | N14: 21.247 | O14: =Table_1__3[[#This Row],[Q3]]-$N$3 -> 2.729 | P14: 25 | R14: 9 | S14: 41 | T14: Arvid LindbladLIN | U14: Racing Bulls | V14: 1:21.247
A15: 10 | B15: 31 | C15: Esteban OconOCO | D15: Haas F1 Team | E15: 1.45 | F15: 29 | H15: 13 | I15: 31 | J15: Esteban OconOCO | K15: Haas F1 Team | L15: 20.759 | M15: 20.491 | O15: =Table_1__3[[#This Row],[Q2]]-$N$3 -> 1.973 | P15: 18 | R15: 13 | S15: 31 | T15: Esteban OconOCO | U15: Haas F1 Team | V15: 1:20.491
A16: 11 | B16: 87 | C16: Oliver BearmanBEA | D16: Haas F1 Team | E16: 1.597 | F16: 31 | H16: 12 | I16: 87 | J16: Oliver BearmanBEA | K16: Haas F1 Team | L16: 21.247 | M16: 20.311 | O16: =Table_1__3[[#This Row],[Q2]]-$N$3 -> 1.793 | P16: 18 | R16: 12 | S16: 87 | T16: Oliver BearmanBEA | U16: Haas F1 Team | V16: 1:20.311
A17: 17 | B17: 55 | C17: Carlos SainzSAI | D17: Williams | E17: 2.524 | F17: 10 | I17: 55 | J17: Carlos SainzSAI | K17: Williams | L17: 59.999 | O17: =Table_1__3[[#This Row],[Q1]]-N3 -> 41.481 | R17: 21 | S17: 55 | T17: Carlos SainzSAI | U17: Williams
A18: 15 | B18: 23 | C18: Alexander AlbonALB | D18: Williams | E18: 2.118 | F18: 32 | H18: 15 | I18: 23 | J18: Alexander AlbonALB | K18: Williams | L18: 21.051 | M18: 20.941 | O18: =Table_1__3[[#This Row],[Q2]]-$N$3 -> 2.423 | P18: 19 | R18: 15 | S18: 23 | T18: Alexander AlbonALB | U18: Williams | V18: 1:20.941
A19: 12 | B19: 27 | C19: Nico HulkenbergHUL | D19: Audi | E19: 1.622 | F19: 34 | H19: 11 | I19: 27 | J19: Nico HulkenbergHUL | K19: Audi | L19: 21.024 | M19: 20.303 | O19: =Table_1__3[[#This Row],[Q2]]-$N$3 -> 1.785 | P19: 18 | R19: 11 | S19: 27 | T19: Nico HulkenbergHUL | U19: Audi | V19: 1:20.303
A20: 14 | B20: 5 | C20: Gabriel BortoletoBOR | D20: Audi | E20: 1.939 | F20: 28 | H20: 10 | I20: 5 | J20: Gabriel BortoletoBOR | K20: Audi | L20: 20.495 | M20: 20.221 | O20: =Table_1__3[[#This Row],[Q2]]-$N$3 -> 1.703 | P20: 14 | R20: 10 | S20: 5 | T20: Gabriel BortoletoBOR | U20: Audi
A21: 20 | B21: 14 | C21: Fernando AlonsoALO | D21: Aston Martin | E21: 4.933 | F21: 18 | H21: 17 | I21: 14 | J21: Fernando AlonsoALO | K21: Aston Martin | L21: 21.969 | O21: =Table_1__3[[#This Row],[Q1]]-$N$3 -> 3.451 | P21: 10 | R21: 17 | S21: 14 | T21: Fernando AlonsoALO | U21: Aston Martin | V21: 1:21.969
A22: 21 | B22: 18 | C22: Lance StrollSTR | D22: Aston Martin | E22: 6.087 | F22: 13 | I22: 18 | J22: Lance StrollSTR | K22: Aston Martin | L22: 59.999 | O22: =Table_1__3[[#This Row],[Q1]]-N3 -> 41.481 | R22: 22 | S22: 18 | T22: Lance StrollSTR | U22: Aston Martin
A23: 22 | B23: 11 | C23: Sergio PerezPER | D23: Cadillac | E23: 59.999 | F23: 2 | H23: 18 | I23: 11 | J23: Sergio PerezPER | K23: Cadillac | L23: 22.605 | O23: =Table_1__3[[#This Row],[Q1]]-$N$3 -> 4.087 | P23: 7 | R23: 18 | S23: 11 | T23: Sergio PerezPER | U23: Cadillac | V23: 1:22.605
A24: 19 | B24: 77 | C24: Valtteri BottasBOT | D24: Cadillac | E24: 3.931 | F24: 28 | H24: 19 | I24: 77 | J24: Valtteri BottasBOT | K24: Cadillac | L24: 23.244 | O24: =Table_1__3[[#This Row],[Q1]]-$N$3 -> 4.726 | P24: 8 | R24: 19 | S24: 77 | T24: Valtteri BottasBOT | U24: Cadillac | V24: 1:23.244
A27: FP3
A28: Pos. | B28: No. | C28: Driver | D28: Team | E28: Time / Gap | F28: Laps
A29: 1 | B29: 63 | C29: George RussellRUS | D29: Mercedes | E29: 0 | F29: 23
A30: 7 | B30: 12 | C30: Kimi AntonelliANT | D30: Mercedes | E30: 1.271 | F30: 18
A31: 3 | B31: 16 | C31: Charles LeclercLEC | D31: Ferrari | E31: 0.774 | F31: 20
A32: 2 | B32: 44 | C32: Lewis HamiltonHAM | D32: Ferrari | E32: 0.616 | F32: 22
A33: 8 | B33: 1 | C33: Lando NorrisNOR | D33: McLaren | E33: 1.39 | F33: 22
A34: 4 | B34: 81 | C34: Oscar PiastriPIA | D34: McLaren | E34: 1.034 | F34: 17
A35: 6 | B35: 3 | C35: Max VerstappenVER | D35: Red Bull Racing | E35: 1.144 | F35: 15
A36: 5 | B36: 6 | C36: Isack HadjarHAD | D36: Red Bull Racing | E36: 1.084 | F36: 15
A37: 15 | B37: 10 | C37: Pierre GaslyGAS | D37: Alpine | E37: 2.018 | F37: 26
A38: 16 | B38: 43 | C38: Franco ColapintoCOL | D38: Alpine | E38: 2.36 | F38: 22
A39: 12 | B39: 30 | C39: Liam LawsonLAW | D39: Racing Bulls | E39: 1.837 | F39: 13
A40: 11 | B40: 41 | C40: Arvid LindbladLIN | D40: Racing Bulls | E40: 1.785 | F40: 15
... A42: 10 | B42: 87 | C42: Oliver BearmanBEA | D42: Haas F1 Team | E42: 1.725 | F42: 18
A43: 21 | B43: 55 | C43: Carlos SainzSAI | D43: Williams | F43: 1
...

Sheet train
A1: round_number | B1: driver | C1: team | D1: engine_supplier | E1: season_avg_finish_pos | F1: season_avg_quali_pos | G1: last3_avg_finish | H1: last3_avg_quali | I1: season_points | J1: championship_position | K1: team_championship_position | L1: team_points | M1: team_avg_finish_pos | N1: team_avg_quali_pos | O1: track_avg_finish_pos | P1: track_avg_quali_pos | Q1: track_wins | R1: track_podiums | S1: driver_mechanical_dnf_rate | T1: team_mechanical_dnfs_this_season | U1: engine_manufacturer_mechanical_dnfs_this_season | V1: fp1_gap_to_fastest | W1: fp2_gap_to_fastest | X1: fp3_gap_to_fastest | Y1: race_or_sprint | Z1: sprint_quali_gap | AA1: sprint_finish_pos | AB1: quali_gap_to_pole | AC1: race_winner
A2: 1 | B2: 63 | C2: 1 | D2: 1 | E2: 10 | F2: 10 | G2: 10 | H2: 10 | I2: 0 | J2: 1 | K2: 1 | L2: 0 | M2: 22 | N2: 22 | O2: 8 | P2: 6.5 | Q2: 1 | R2: 3 | S2: 0 | T2: 0 | U2: 0 | V2: 1.104 | W2: 0.32 | X2: 0 | Y2: 0 | Z2: 0 | AA2: 0 | AB2: 0 | AC2: 1
A3: 1 | B3: 12 | C3: 1 | D3: 1 | E3: 10 | F3: 10 | G3: 10 | H3: 10 | I3: 0 | J3: 1 | K3: 1 | L3: 0 | M3: 22 | N3: 22 | O3: 3 | P3: 9 | Q3: 0 | R3: 1 | S3: 0 | T3: 0 | U3: 0 | V3: 1.109 | W3: 0.214 | X3: 1.271 | Y3: 0 | Z3: 0 | AA3: 0 | AB3: 0.293 | AC3: 0
A4: 1 | B4: 16 | C4: 2 | D4: 2 | E4: 10 | F4: 10 | G4: 10 | H4: 10 | I4: 0 | J4: 1 | K4: 1 | L4: 0 | M4: 22 | N4: 22 | O4: 5.33 | P4: 6.57 | Q4: 1 | R4: 3 | S4: 0 | T4: 0 | U4: 0 | V4: 0 | W4: 0.562 | X4: 0.774 | Y4: 0 | Z4: 0 | AA4: 0 | AB4: 0.809 | AC4: 0
A5: 1 | B5: 44 | C5: 2 | D5: 2 | E5: 10 | F5: 10 | G5: 10 | H5: 10 | I5: 0 | J5: 1 | K5: 1 | L5: 0 | M5: 22 | N5: 22 | O5: 3.27 | P5: 4.44 | Q5: 2 | R5: 10 | S5: 0 | T5: 0 | U5: 0 | V5: 0.469 | W5: 0.321 | X5: 0.616 | Y5: 0 | Z5: 0 | AA5: 0 | AB5: 0.96 | AC5: 0
A6: 1 | B6: 1 | C6: 3 | D6: 1 | E6: 10 | F6: 10 | G6: 10 | H6: 10 | I6: 0 | J6: 1 | K6: 1 | L6: 0 | M6: 22 | N6: 22 | O6: 5.33 | P6: 5.83 | Q6: 1 | R6: 2 | S6: 0 | T6: 0 | U6: 0 | V6: 4.124 | W6: 1.065 | X6: 1.39 | Y6: 0 | Z6: 0 | AA6: 0 | AB6: 0.957 | AC6: 0
A7: 1 | B7: 81 | C7: 3 | D7: 1 | E7: 10 | F7: 10 | G7: 10 | H7: 10 | I7: 0 | J7: 1 | K7: 1 | L7: 0 | M7: 22 | N7: 22 | O7: 7 | P7: 7 | Q7: 0 | R7: 0 | S7: 0 | T7: 0 | U7: 0 | V7: 1.046 | W7: 0 | X7: 1.034 | Y7: 0 | Z7: 0 | AA7: 0 | AB7: 0.862 | AC7: 0
A8: 1 | B8: 3 | C8: 4 | D8: 3 | E8: 10 | F8: 10 | G8: 10 | H8: 10 | I8: 0 | J8: 1 | K8: 1 | L8: 0 | M8: 22 | N8: 22 | O8: 4.71 | P8: 5.6 | Q8: 1 | R8: 3 | S8: 0 | T8: 0 | U8: 0 | V8: 0.522 | W8: 0.637 | X8: 1.144 | Y8: 0 | Z8: 0 | AA8: 0 | AB8: 41.481 | AC8: 0
A9: 1 | B9: 6 | C9: 4 | D9: 3 | E9: 10 | F9: 10 | G9: 10 | H9: 10 | I9: 0 | J9: 1 | K9: 1 | L9: 0 | M9: 22 | N9: 22 | O9: 7 | P9: 20 | Q9: 0 | R9: 0 | S9: 0 | T9: 0 | U9: 0 | V9: 0.82 | W9: 1.212 | X9: 1.084 | Y9: 0 | Z9: 0 | AA9: 0 | AB9: 0.785 | AC9: 0
A10: 2 | B10: 63 | C10: 1 | D10: 1 | E10: 1 | F10: 1 | G10: 1 | H10: 1 | I10: 25 | J10: 1 | K10: 1 | L10: 43 | M10: 1.5 | N10: 1.5 | O10: 6.75 | P10: 7.25 | Q10: 0 | R10: 1 | S10: 0 | T10: 0 | U10: 2 | V10: 0 | W10: 0 | X10: 0 | Y10: 1 | Z10: 0 | AA10: 1 | AB10: 0.222 | AC10: 0
A11: 2 | B11: 12 | C11: 1 | D11: 1 | E11: 2 | F11: 2 | G11: 2 | H11: 2 | I11: 18 | J11: 2 | K11: 1 | L11: 43 | M11: 1.5 | N11: 1.5 | O11: 3.5 | P11: 4.5 | Q11: 0 | R11: 0 | S11: 0 | T11: 0 | U11: 2 | V11: 0.12 | W11: 0 | X11: 0 | Y11: 1 | Z11: 0.289 | AA11: 5 | AB11: 0 | AC11: 1
A12: 2 | B12: 16 | C12: 2 | D12: 2 | E12: 3 | F12: 4 | G12: 3 | H12: 4 | I12: 15 | J12: 3 | K12: 2 | L12: 27 | M12: 3.5 | N12: 5.5 | O12: 8 | P12: 7.8 | Q12: 0 | R12: 0 | S12: 0 | T12: 0 | U12: 1 | V12: 0.858 | W12: 0 | X12: 0 | Y12: 1 | Z12: 1.008 | AA12: 2 | AB12: 0.364 | AC12: 0
A13: 2 | B13: 44 | C13: 2 | D13: 2 | E13: 4 | F13: 7 | G13: 4 | H13: 7 | I13: 12 | J13: 4 | K13: 2 | L13: 27 | M13: 3.5 | N13: 5.5 | O13: 3.07 | P13: 5.31 | Q13: 6 | R13: 10 | S13: 0 | T13: 0 | U13: 1 | V13: 1.388 | W13: 0 | X13: 0 | Y13: 1 | Z13: 0.641 | AA13: 3 | AB13: 0.315 | AC13: 0
... A40: 5 | B40: 3 | C40: 4 | D40: 3 | E40: 8.75 | F40: 10.25 | G40: 9.6666667 | H40: 7 | I40: 22 | J40: 7 | K40: 4 | L40: 26 | M40: 12.125 | N40: 10.375 | O40: 3.89 | P40: 5.3 | Q40: 3 | R40: 6 | S40: 1 | T40: 3 | U40: 3 | V40: 0.964 | W40: 0 | X40: 0 | Y40: 1 | Z40: 0.539 | AA40: 7 | AB40: 0.329 | AC40: 0
A41: 5 | B41: 6 | C41: 4 | D41: 3 | E41: 15.5 | F41: 10.5 | G41: 14 | H41: 13 | I41: 4 | J41: 14 | K41: 4 | L41: 26 | M41: 12.125 | N41: 10.375 | O41: 10.5 | P41: 9.5 | Q41: 0 | R41: 0 | S41: 2 | T41: 3 | U41: 3 | V41: 2.851 | W41: 0 | X41: 0 | Z41: 0.64 | AA41: 21 | AB41: 0.357 | AC41: 0
A42: 6 | B42: 63 | C42: 1 | D42: 1 | E42: 6 | F42: 2.2 | G42: 9 | H42: 2.6666667 | I42: 88 | J42: 2 | K42: 1 | L42: 219 | M42: 3.6 | N42: 1.8 | O42: 9.57 | P42: 10.43 | Q42: 0 | R42: 0 | S42: 1 | T42: 1 | U42: 9 | V42: 1.005 | W42: 0.379 | X42: 0.763 | Y42: 0 | Z42: 0 | AA42: 0 | AB42: 0.394 | AC42: 0
A43: 6 | B43: 12 | C43: 1 | D43: 1 | E43: 1.2 | F43: 1.4 | G43: 1 | H43: 1.3333333 | I43: 131 | J43: 1 | K43: 1 | L43: 219 | M43: 3.6 | N43: 1.8 | O43: 9.5 | P43: 8 | Q43: 0 | R43: 0 | S43: 0 | T43: 1 | U43: 9 | V43: 0.559 | W43: 0.503 | X43: 0 | Y43: 0 | Z43: 0 | AA43: 0 | AB43: 0 | AC43: 1
A44: 6 | B44: 16 | C44: 2 | D44: 2 | E44: 4.4 | F44: 4.6 | G44: 5 | H44: 5 | I44: 75 | J44: 3 | K44: 2 | L44: 147 | M44: 4.3 | N44: 5 | O44: 6.2 | P44: 5.5 | Q44: 1 | R44: 2 | S44: 0 | T44: 0 | U44: 2 | V44: 0 | W44: 0.111 | X44: 0.327 | Y44: 0 | Z44: 0 | AA44: 0 | AB44: 0.3 | AC44: 0
A45: 6 | B45: 44 | C45: 2 | D45: 2 | E45: 4.2 | F45: 5.4 | G45: 4.6666667 | H45: 5.6666667 | I45: 72 | J45: 4 | K45: 2 | L45: 147 | M45: 4.3 | N45: 5 | O45: 4.47 | P45: 5.42 | Q45: 3 | R45: 8 | S45: 0 | T45: 0 | U45: 2 | V45: 0.226 | W45: 0 | X45: 0.331 | Y45: 0 | Z45: 0 | AA45: 0 | AB45: 0.228 | AC45: 0
A46: 6 | B46: 1 | C46: 3 | D46: 1 | E46: 10 | F46: 4.8 | G46: 8.3333333 | H46: 4 | I46: 58 | J46: 5 | K46: 3 | L46: 106 | M46: 10.6 | N46: 4.8 | O46: 5.67 | P46: 6.43 | Q46: 1 | R46: 2 | S46: 2 | T46: 4 | U46: 9 | V46: 1.313 | W46: 2.248 | X46: 1.286 | Y46: 0 | Z46: 0 | AA46: 0 | AB46: 0.714 | AC46: 0
A47: 6 | B47: 81 | C47: 3 | D47: 1 | E47: 11.2 | F47: 4.8 | G47: 5.3333333 | H47: 4.6666667 | I47: 48 | J47: 6 | K47: 3 | L47: 106 | M47: 10.6 | N47: 4.8 | O47: 5 | P47: 5.75 | Q47: 0 | R47: 2 | S47: 2 | T47: 4 | U47: 9 | V47: 1.587 | W47: 1.062 | X47: 0.978 | Y47: 0 | Z47: 0 | AA47: 0 | AB47: 0.573 | AC47: 0
A48: 6 | B48: 3 | C48: 4 | D48: 3 | E48: 7.6 | F48: 9.4 | G48: 5.3333333 | H48: 6.3333333 | I48: 37 | J48: 7 | K48: 4 | L48: 51 | M48: 10.5 | N48: 9.6 | O48: 4.13 | P48: 6.91 | Q48: 2 | R48: 3 | S48: 1 | T48: 4 | U48: 5 | V48: 0.513 | W48: 0.168 | X48: 0.942 | Y48: 0 | Z48: 0 | AA48: 0 | AB48: 0.043 | AC48: 0
A49: 6 | B49: 6 | C49: 4 | D49: 3 | E49: 13.4 | F49: 9.8 | G49: 13 | H49: 12.333333 | I49: 14 | J49: 11 | K49: 4 | L49: 51 | M49: 10.5 | N49: 9.6 | O49: 5 | P49: 5 | Q49: 0 | R49: 0 | S49: 2 | T49: 4 | U49: 5 | V49: 2.17 | W49: 1.061 | X49: 1.157 | Y49: 0 | Z49: 0 | AA49: 0 | AB49: 0.383 | AC49: 0
A50: 7 | B50: 63 | C50: 1 | D50: 1 | E50: 7 | F50: 2.8333333 | G50: 11.666667 | H50: 4 | I50: 88 | J50: 3 | K50: 1 | L50: 244 | M50: 4.0833333 | N50: 2.0833333 | O50: 8 | P50: 9.63 | Q50: 0 | R50: 1 | S50: 1 | T50: 1 | U50: 10 | V50: 0 | W50: 0.009 | X50: 0 | Y50: 0 | Z50: 0 | AA50: 0 | AB50: 0 | AC50: 0
A51: 7 | B51: 12 | C51: 1 | D51: 1 | E51: 1.1666667 | F51: 1.3333333 | G51: 1 | H51: 1.3333333 | I51: 156 | J51: 1 | K51: 1 | L51: 244 | M51: 4.0833333 | N51: 2.0833333 | O51: 17 | P51: 4.5 | Q51: 0 | R51: 0 | S51: 0 | T51: 1 | U51: 10 | V51: 0.05 | W51: 0.589 | X51: 0.821 | Y51: 0 | Z51: 0 | AA51: 0 | AB51: 0.319 | AC51: 0
A52: 7 | B52: 16 | C52: 2 | D52: 2 | E52: 6.5 | F52: 4.5 | G52: 9.6666667 | H52: 5 | I52: 75 | J52: 4 | K52: 2 | L52: 165 | M52: 5.1666667 | N52: 4.75 | O52: 7.57 | P52: 8.22 | Q52: 0 | R52: 1 | S52: 1 | T52: 1 | U52: 3 | V52: 0.52 | W52: 0.373 | X52: 0.243 | Y52: 0 | Z52: 0 | AA52: 0 | AB52: 26.32 | AC52: 0
A53: 7 | B53: 44 | C53: 2 | D53: 2 | E53: 3.8333333 | F53: 5 | G53: 3.3333333 | H53: 4.6666667 | I53: 90 | J53: 2 | K53: 2 | L53: 165 | M53: 5.1666667 | N53: 4.75 | O53: 3.95 | P53: 4.25 | Q53: 7 | R53: 12 | S53: 0 | T53: 1 | U53: 3 | V53: 0.52 | W53: 1.205 | X53: 0.702 | Y53: 0 | Z53: 0 | AA53: 0 | AB53: 0.064 | AC53: 1
... A59: 8 | B59: 12 | C59: 1 | D59: 1 | E59: 3.2857143 | F59: 1.5714286 | G59: 6 | H59: 2 | I59: 156 | J59: 1 | K59: 1 | L59: 262 | M59: 4.7857143 | N59: 2.0714286 | O59: 20 | P59: 9 | Q59: 0 | R59: 0 | S59: 1 | T59: 2 | U59: 12 | V59: 0 | W59: 0 | X59: 0.038 | Y59: 0 | Z59: 0 | AA59: 0 | AB59: 0.301 | AC59: 0
A60: 8 | B60: 16 | C60: 2 | D60: 2 | E60: 7.7142857 | F60: 5.2857143 | G60: 12 | H60: 7.3333333 | I60: 75 | J60: 4 | K60: 2 | L60: 190 | M60: 5.5714286 | N60: 4.9285714 | O60: 4.75 | P60: 6.13 | Q60: 1 | R60: 5 | S60: 2 | T60: 2 | U60: 4 | W60: 0.841 | X60: 0.356 | Y60: 0 | Z60: 0 | AA60: 0 | AB60: 0.236 | AC60: 0
A61: 8 | B61: 44 | C61: 2 | D61: 2 | E61: 3.4285714 | F61: 4.5714286 | G61: 1.6666667 | H61: 3.3333333 | I61: 115 | J61: 2 | K61: 2 | L61: 190 | M61: 5.5714286 | N61: 4.9285714 | O61: 3.37 | P61: 4.67 | Q61: 2 | R61: 4 | S61: 0 | T61: 2 | U61: 4 | V61: 0.665 | W61: 0.597 | X61: 0.115 | Y61: 0 | Z61: 0 | AA61: 0 | AB61: 0.295 | AC61: 0
A62: 8 | B62: 1 | C62: 3 | D62: 1 | E62: 10.285714 | F62: 5.1428571 | G62: 13.333333 | H62: 5 | I62: 73 | J62: 5 | K62: 3 | L62: 141 | M62: 9.8571429 | N62: 5.2857143 | O62: 6.29 | P62: 3.86 | Q62: 1 | R62: 3 | S62: 3 | T62: 5 | U62: 12 | V62: 1.077 | W62: 0.325 | X62: 0.264 | Y62: 0 | Z62: 0 | AA62: 0 | AB62: 0.389 | AC62: 0
A63: 8 | B63: 81 | C63: 3 | D63: 1 | E63: 9.4285714 | F63: 5.4285714 | G63: 7 | H63: 6 | I63: 68 | J63: 6 | K63: 3 | L63: 141 | M63: 9.8571429 | N63: 5.2857143 | O63: 6.667 | P63: 7.67 | Q63: 0 | R63: 2 | S63: 2 | T63: 5 | U63: 12 | V63: 0.117 | W63: 0.237 | X63: 0.248 | Y63: 0 | Z63: 0 | AA63: 0 | AB63: 0.398 | AC63: 0
A64: 8 | B64: 3 | C64: 4 | D64: 3 | E64: 9.1428571 | F64: 7.7142857 | G64: 9.6666667 | H64: 4.3333333 | I64: 55 | J64: 7 | K64: 4 | L64: 89 | M64: 10.071429 | N64: 8.1428571 | O64: 2.63 | P64: 3.55 | Q64: 4 | R64: 6 | S64: 2 | T64: 4 | U64: 6 | V64: 0.281 | W64: 0.55 | X64: 0.273 | Y64: 0 | Z64: 0 | AA64: 0 | AB64: 0.362 | AC64: 0
A65: 8 | B65: 6 | C65: 4 | D65: 3 | E65: 11 | F65: 8.5714286 | G65: 5 | H65: 6 | I65: 34 | J65: 9 | K65: 4 | L65: 89 | M65: 10.071429 | N65: 8.1428571 | O65: 12 | P65: 13 | Q65: 0 | R65: 0 | S65: 2 | T65: 4 | U65: 6 | V65: 1.685 | W65: 0.744 | X65: 0.816 | Y65: 0 | Z65: 0 | AA65: 0 | AB65: 0.519 | AC65: 0

Sheet test
A1: round_number | B1: driver | C1: team | D1: engine_supplier | E1: season_avg_finish_pos | F1: season_avg_quali_pos | G1: last3_avg_finish | H1: last3_avg_quali | I1: season_points | J1: championship_position | K1: team_championship_position | L1: team_points | M1: team_avg_finish_pos | N1: team_avg_quali_pos | O1: track_avg_finish_pos | P1: track_avg_quali_pos | Q1: track_wins | R1: track_podiums | S1: driver_mechanical_dnf_rate | T1: team_mechanical_dnfs_this_season | U1: engine_manufacturer_mechanical_dnfs_this_season | V1: fp1_gap_to_fastest | W1: fp2_gap_to_fastest | X1: fp3_gap_to_fastest | Y1: race_or_sprint | Z1: sprint_quali_gap | AA1: sprint_finish_pos | AB1: quali_gap_to_pole | AC1: race_winner
A2: 7 | B2: 63 | C2: 1 | D2: 1 | E2: 5.625 | F2: 2.375 | G2: 5 | H2: 2.6666667 | I2: 131 | J2: 2 | K2: 1 | L2: =I2+I3 -> 302 | M2: 4.0833333 | N2: 2.0833333 | O2: 11.83 | P2: 10.63 | Q2: 0 | R2: 0
A3: 7 | B3: 12 | C3: 1 | D3: 1 | E3: 3.25 | F3: 1.875 | G3: 6.6666667 | H3: 2.6666667 | I3: 171 | J3: 1 | K3: 1 | L3: =L2 -> 302 | M3: 4.0833333 | N3: 2.0833333 | O3: 16 | P3: 7 | Q3: 0 | R3: 0
A4: 7 | B4: 16 | C4: 2 | D4: 2 | E4: 7.75 | F4: 4.875 | G4: 13.333333 | H4: 5.3333333 | I4: 79 | J4: 6 | K4: 2 | L4: =I4+I5 -> 204 | M4: 5.1666667 | N4: 4.75 | O4: 6.63 | P4: 5.78 | Q4: 0 | R4: 3
A5: 7 | B5: 44 | C5: 2 | D5: 2 | E5: 3.625 | F5: 4.375 | G5: 2.6666667 | H5: 2.6666667 | I5: 125 | J5: 3 | K5: 2 | L5: =L4 -> 204 | M5: 5.1666667 | N5: 4.75 | O5: 3 | P5: 4.1 | Q5: 9 | R5: 15
A6: 7 | B6: 1 | C6: 3 | D6: 1 | E6: 9.875 | F6: 5.25 | G6: 9.6666667 | H6: 6 | I6: 79 | J6: 5 | K6: 3 | L6: =I6+I7 -> 159 | M6: 10.833333 | N6: 5.25 | O6: 5.13 | P6: 5.25 | Q6: 1 | R6: 3
A7: 7 | B7: 81 | C7: 3 | D7: 1 | E7: 8.75 | F7: 5.625 | G7: 4.6666667 | H7: 7 | I7: 80 | J7: 4 | K7: 3 | L7: =L6 -> 159 | M7: 10.833333 | N7: 5.25 | O7: 3.33 | P7: 3.33 | Q7: 0 | R7: 1
A8: 7 | B8: 3 | C8: 4 | D8: 3 | E8: 8.25 | F8: 7.375 | G8: 9.3333333 | H8: 4 | I8: 73 | J8: 7 | K8: 4 | L8: =I8+I9 -> 115 | M8: 10.916667 | N8: 8.5833333 | O8: 4.4 | P8: 3.75 | Q8: 2 | R8: 5
A9: 7 | B9: 6 | C9: 4 | D9: 3 | E9: 10.375 | F9: 8.5 | G9: 5.3333333 | H9: 6.3333333 | I9: 42 | J9: 8 | K9: 4 | L9: =L8 -> 115 | M9: 10.916667 | N9: 8.5833333 | O9: 17 | P9: 13 | Q9: 0 | R9: 0

Sheet code & pos
A1: TEAM_code | B1: Name | D1: Driver_code | E1: Driver Name | F1: Race_Mel | G1: Race_China | H1: Race_Jap | I1: Race_Miami | J1: Race_Canada | K1: Race_Monaco | L1: Race_Barcelona | M1: Race_Austria | N1: Seasson Av | O1: Last3av | P1: code | Q1: engine | T1: Round | U1: Name
A2: 1 | B2: Merc | D2: 63 | E2: Russell | F2: 1 | G2: 2 | H2: 4 | I2: 4 | J2: 19 | K2: 12 | L2: 2 | M2: 1 | N2: =SUM(F2:M2)/COUNT(F2:M2) -> 5.625 | O2: =SUM(K2:M2)/COUNT(K2:M2) -> 5 | P2: 1 | Q2: Merc | T2: 1 | U2: Australia
A3: 2 | B3: Ferrari | D3: 12 | E3: Antonelli | F3: 2 | G3: 1 | H3: 1 | I3: 1 | J3: 1 | K3: 1 | L3: 16 | M3: 3 | N3: =SUM(F3:M3)/COUNT(F3:M3) -> 3.25 | O3: =SUM(K3:M3)/COUNT(K3:M3) -> 6.6666667 | P3: 2 | Q3: Ferrari | T3: 2 | U3: China
A4: 3 | B4: McLaren | D4: 16 | E4: Leclerc | F4: 3 | G4: 4 | H4: 3 | I4: 8 | J4: 4 | K4: 17 | L4: 15 | M4: 8 | N4: =SUM(F4:M4)/COUNT(F4:M4) -> 7.75 | O4: =SUM(K4:M4)/COUNT(K4:M4) -> 13.333333 | P4: 3 | Q4: RBPT | T4: 3 | U4: Japan
A5: 4 | B5: RedBull | D5: 44 | E5: Hamilton | F5: 4 | G5: 3 | H5: 6 | I5: 6 | J5: 2 | K5: 2 | L5: 1 | M5: 5 | N5: =SUM(F5:M5)/COUNT(F5:M5) -> 3.625 | O5: =SUM(K5:M5)/COUNT(K5:M5) -> 2.6666667 | P5: 4 | Q5: Audi | T5: 4 | U5: Miami
A6: 5 | B6: Alpine | D6: 4 | E6: Norris | F6: 5 | G6: 20 | H6: 5 | I6: 2 | J6: 18 | K6: 19 | L6: 3 | M6: 7 | N6: =SUM(F6:M6)/COUNT(F6:M6) -> 9.875 | O6: =SUM(K6:M6)/COUNT(K6:M6) -> 9.6666667 | P6: 5 | Q6: Honda | T6: 5 | U6: Canada
A7: 6 | B7: RacingBulls | D7: 81 | E7: Piastri | F7: 21 | G7: 19 | H7: 2 | I7: 3 | J7: 11 | K7: 5 | L7: 5 | M7: 4 | N7: =SUM(F7:M7)/COUNT(F7:M7) -> 8.75 | O7: =SUM(K7:M7)/COUNT(K7:M7) -> 4.6666667 | T7: 6 | U7: Monaco
A8: 7 | B8: Hass | D8: 3 | E8: Verstappen | F8: 6 | G8: 16 | H8: 8 | I8: 5 | J8: 3 | K8: 22 | L8: 4 | M8: 2 | N8: =SUM(F8:M8)/COUNT(F8:M8) -> 8.25 | O8: =SUM(K8:M8)/COUNT(K8:M8) -> 9.3333333 | T8: 7 | U8: Barcelona
A9: 8 | B9: Williams | D9: 6 | E9: Hadjar | F9: 20 | G9: 8 | H9: 12 | I9: 22 | J9: 5 | K9: 4 | L9: 6 | M9: 6 | N9: =SUM(F9:M9)/COUNT(F9:M9) -> 10.375 | O9: =SUM(K9:M9)/COUNT(K9:M9) -> 5.3333333 | T9: 8 | U9: Austria
A10: 9 | B10: Audi | D10: 10 | E10: Gasly | F10: 10 | G10: 6 | H10: 7 | I10: 21 | J10: 8 | K10: 3 | L10: 7 | M10: 13 | N10: =SUM(F10:M10)/COUNT(F10:M10) -> 9.375 | O10: =SUM(K10:M10)/COUNT(K10:M10) -> 7.6666667 | T10: 9
A11: 10 | B11: Aston | D11: 43 | E11: Colapinto | F11: 14 | G11: 10 | H11: 16 | I11: 7 | J11: 6 | K11: 14 | L11: 10 | M11: 15 | N11: =SUM(F11:M11)/COUNT(F11:M11) -> 11.5 | O11: =SUM(K11:M11)/COUNT(K11:M11) -> 13
A12: 11 | B12: Cadiliac | D12: 30 | E12: Lawson | F12: 13 | G12: 7 | H12: 9 | I12: 20 | J12: 7 | K12: 6 | L12: 8 | M12: 9 | N12: =SUM(F12:M12)/COUNT(F12:M12) -> 9.875 | O12: =SUM(K12:M12)/COUNT(K12:M12) -> 7.6666667
D13: 41 | E13: Lindblad | F13: 8 | G13: 12 | H13: 14 | I13: 14 | J13: 22 | K13: 7 | L13: 9 | M13: 10 | N13: =SUM(F13:M13)/COUNT(F13:M13) -> 12 | O13: =SUM(K13:M13)/COUNT(K13:M13) -> 8.6666667
D14: 31 | E14: Ocon | F14: 11 | G14: 14 | H14: 10 | I14: 13 | J14: 14 | K14: 9 | L14: 13 | M14: 16 | N14: =SUM(F14:M14)/COUNT(F14:M14) -> 12.5 | O14: =SUM(K14:M14)/COUNT(K14:M14) -> 12.666667
D15: 87 | E15: Bearman | F15: 7 | G15: 5 | H15: 22 | I15: 11 | J15: 10 | K15: 20 | L15: 17 | M15: 14 | N15: =SUM(F15:M15)/COUNT(F15:M15) -> 13.25 | O15: =SUM(K15:M15)/COUNT(K15:M15) -> 17
D16: 55 | E16: Sainz | F16: 15 | G16: 9 | H16: 15 | I16: 9 | J16: 9 | K16: 16 | L16: 12 | M16: 20 | N16: =SUM(F16:M16)/COUNT(F16:M16) -> 13.125 | O16: =SUM(K16:M16)/COUNT(K16:M16) -> 16
D17: 23 | E17: Albon | F17: 12 | G17: 22 | H17: 20 | I17: 10 | J17: 21 | K17: 8 | L17: 18 | M17: 17 | N17: =SUM(F17:M17)/COUNT(F17:M17) -> 16 | O17: =SUM(K17:M17)/COUNT(K17:M17) -> 14.333333
D18: 27 | E18: Hulkenburg | F18: 22 | G18: 11 | H18: 11 | I18: 19 | J18: 12 | K18: 13 | L18: 20 | M18: 12 | N18: =SUM(F18:M18)/COUNT(F18:M18) -> 15 | O18: =SUM(K18:M18)/COUNT(K18:M18) -> 15
D19: 5 | E19: Bortoleto | F19: 9 | G19: 21 | H19: 13 | I19: 12 | J19: 13 | K19: 11 | L19: 11 | M19: 11 | N19: =SUM(F19:M19)/COUNT(F19:M19) -> 12.625 | O19: =SUM(K19:M19)/COUNT(K19:M19) -> 11
D20: 14 | E20: Alonso | F20: 18 | G20: 17 | H20: 18 | I20: 15 | J20: 20 | K20: 10 | L20: 19 | M20: 18 | N20: =SUM(F20:M20)/COUNT(F20:M20) -> 16.875 | O20: =SUM(K20:M20)/COUNT(K20:M20) -> 15.666667
D21: 18 | E21: Stroll | F21: 17 | G21: 18 | H21: 21 | I21: 17 | J21: 15 | K21: 18 | L21: 22 | M21: 19 | N21: =SUM(F21:M21)/COUNT(F21:M21) -> 18.375 | O21: =SUM(K21:M21)/COUNT(K21:M21) -> 19.666667
D22: 11 | E22: Perez | F22: 16 | G22: 15 | H22: 17 | I22: 16 | J22: 17 | K22: 15 | L22: 14 | M22: 21 | N22: =SUM(F22:M22)/COUNT(F22:M22) -> 16.375 | O22: =SUM(K22:M22)/COUNT(K22:M22) -> 16.666667
D23: 77 | E23: Bottas | F23: 19 | G23: 13 | H23: 19 | I23: 18 | J23: 16 | K23: 21 | L23: 21 | M23: 22 | N23: =SUM(F23:M23)/COUNT(F23:M23) -> 18.625 | O23: =SUM(K23:M23)/COUNT(K23:M23) -> 21.333333
D25: Driver_code | E25: Driver Name | F25: Q_Mel | G25: Q_China | H25: Q_Jap | I25: Q_Miami | J25: Q_Canada | K25: Q_Monaco | L25: Q_Barcelona | M25: Q_Austria | N25: Seasson Av | O25: Last3av
D26: 63 | E26: Russell | F26: 1 | G26: 2 | H26: 2 | I26: 5 | J26: 1 | K26: 6 | L26: 1 | M26: 1 | N26: =SUM(F26:M26)/COUNT(F26:M26) -> 2.375 | O26: =SUM(K26:M26)/COUNT(K26:M26) -> 2.6666667
D27: 12 | E27: Antonelli | F27: 2 | G27: 1 | H27: 1 | I27: 1 | J27: 2 | K27: 1 | L27: 3 | M27: 4 | N27: =SUM(F27:M27)/COUNT(F27:M27) -> 1.875 | O27: =SUM(K27:M27)/COUNT(K27:M27) -> 2.6666667
D28: 16 | E28: Leclerc | F28: 4 | G28: 4 | H28: 4 | I28: 3 | J28: 8 | K28: 4 | L28: 10 | M28: 2 | N28: =SUM(F28:M28)/COUNT(F28:M28) -> 4.875 | O28: =SUM(K28:M28)/COUNT(K28:M28) -> 5.3333333
D29: 44 | E29: Hamilton | F29: 7 | G29: 3 | H29: 6 | I29: 6 | J29: 5 | K29: 3 | L29: 2 | M29: 3 | N29: =SUM(F29:M29)/COUNT(F29:M29) -> 4.375 | O29: =SUM(K29:M29)/COUNT(K29:M29) -> 2.6666667
D30: 4 | E30: Norris | F30: 6 | G30: 6 | H30: 5 | I30: 4 | J30: 3 | K30: 8 | L30: 4 | M30: 6 | N30: =SUM(F30:M30)/COUNT(F30:M30) -> 5.25 | O30: =SUM(K30:M30)/COUNT(K30:M30) -> 6
D31: 81 | E31: Piastri | F31: 5 | G31: 5 | H31: 3 | I31: 7 | J31: 4 | K31: 7 | L31: 7 | M31: 7 | N31: =SUM(F31:M31)/COUNT(F31:M31) -> 5.625 | O31: =SUM(K31:M31)/COUNT(K31:M31) -> 7
D32: 3 | E32: Verstappen | F32: 20 | G32: 8 | H32: 11 | I32: 2 | J32: 6 | K32: 2 | L32: 5 | M32: 5 | N32: =SUM(F32:M32)/COUNT(F32:M32) -> 7.375 | O32: =SUM(K32:M32)/COUNT(K32:M32) -> 4
D33: 6 | E33: Hadjar | F33: 3 | G33: 9 | H33: 8 | I33: 22 | J33: 7 | K33: 5 | L33: 6 | M33: 8 | N33: =SUM(F33:M33)/COUNT(F33:M33) -> 8.5 | O33: =SUM(K33:M33)/COUNT(K33:M33) -> 6.3333333
D34: 10 | E34: Gasly | F34: 14 | G34: 7 | H34: 7 | I34: 9 | J34: 14 | K34: 9 | L34: 14 | M34: 11 | N34: =SUM(F34:M34)/COUNT(F34:M34) -> 10.625 | O34: =SUM(K34:M34)/COUNT(K34:M34) -> 11.333333
D35: 43 | E35: Colapinto | F35: 16 | G35: 12 | H35: 15 | I35: 8 | J35: 10 | K35: 14 | L35: 13 | M35: 16 | N35: =SUM(F35:M35)/COUNT(F35:M35) -> 13 | O35: =SUM(K35:M35)/COUNT(K35:M35) -> 14.333333
D36: 30 | E36: Lawson | F36: 8 | G36: 14 | H36: 14 | I36: 11 | J36: 12 | K36: 10 | L36: 8 | M36: 9 | N36: =SUM(F36:M36)/COUNT(F36:M36) -> 10.75 | O36: =SUM(K36:M36)/COUNT(K36:M36) -> 9
D37: 41 | E37: Lindblad | F37: 9 | G37: 15 | H37: 10 | I37: 16 | J37: 9 | K37: 15 | L37: 11 | M37: 10 | N37: =SUM(F37:M37)/COUNT(F37:M37) -> 11.875 | O37: =SUM(K37:M37)/COUNT(K37:M37) -> 12
... D47: 77 | E47: Bottas | F47: 19 | G47: 20 | H47: 20 | I47: 19 | J47: 21 | K47: 20 | L47: 20 | M47: 20 | N47: =SUM(F47:M47)/COUNT(F47:M47) -> 19.875 | O47: =SUM(K47:M47)/COUNT(K47:M47) -> 20
